# 异常处理

![img](https://www.python.jp/pages/python_logo2.png)

[[toc]]

## 异常简介

代码执行时遇到错误即出现异常

出现异常后程序就会停止，**后续代码不会执行**，控制台会并提示错误类型与错误信息

```python
# 若用户输入的不是数字会报错抛出异常与错误信息
input_num = int(input('请输入: '))
# ValueError: invalid literal for int() with base 10: 'a'

# 程序执行被终止后续代码不会执行
```

<br/>

## 异常处理

通过 `try ... except...` 进行异常处理，即使遇到错误后续代码仍会继续执行

**`try` 无法单独使用，必须和一个或以上的 `except` 代码块连用**

::: tip try...except...

```python
try:
    # 尝试执行的代码
except:
    # 若出现异常则执行的代码
```

:::

::: tip try...except...else...finally

```python
try:
    # 尝试执行的代码
except:
    # 若出现异常则执行的代码
else:
  	# 可选
  	# 若没出现异常则执行的代码
finally:
  	# 可选
  	# 无论是否有异常都会执行的代码
```

:::

```python
def func_1():
    return int(input("请输入一个整数："))


def func_2():
    return 10/int(input("请输入一个能被 10 除的数："))


try:
    res_1 = func_1()
    res_2 = func_2()
except:
    print('出错了')
else:
    print(res_1)
    print(res_2)
```

---

### 变量传递

```python
def func():
    f = None
    try:
        f = open('./011.txt')
        return 1
    except:
        return 2
    finally:
        if f:
            f.close()
        return 4


print(func())
```

```python
a = 10
try:
    a = 20
    b = 20
    # raise Exception()
except:
    a += 1
    b += 1
    print(a, b)
else:
    a += 2
    b += 2
    print(a, b)
finally:
    print(a, b)

print(a, b)
```

<br/>

## 异常捕获 except

`try` 中代码在执行时若出现异常底层会产生一个异常的类型

可通过 `except` 来捕获异常类型（**catch**）并执行对应操作

---

### 捕获所有异常

只要出现异常不论异常类型 `except` 代码块都会被执行

```python
try:
    # 尝试执行的代码
except:
    # 只要出现异常，不论异常类型，此处都会执行
```

```python
try:
    input_num = int(input('请输入整数: '))
except:
    print('出现错误')
```

::: tip

`except` 会捕获所有异常，但**无法具体到异常类型和具体错误信息**

**若要获取具体错误信息可指明捕获 `Exception` 类**，[详见下文](#指定异常类型)

即指明捕获所有异常类型的父类，从而来实现所有异常的统一捕获

```python
try:
    # 尝试执行的代码
except Exception as 具体错误信息:
    # 只要出现继承了 Exception 类的异常类型，此处都会执行
```

:::

---

### 捕获指定异常类型

可在 `except` 后指定要处理的[异常的类型](#常见错误类型)，仅在该异常类型出现时才处理

```python
try:
    # 尝试执行的代码

except 错误类型A:
    # 针对类型的处理

except 错误类型B:
    # 针对类型的处理

except (错误类型C, 错误类型D, 错误类型E):
    # 针对类型的处理
```

```python
try:
    num = int(input('请输入整数做分母被 10 除: '))
    result = 10/num

except ValueError:
    print('输入的不是数字')

except ZeroDivisionError:
    print('0 不能作为分母')

else:
    print(result)
```

---

### 捕获未知异常

逐一指明类型仍然太复杂，若遇到未指定类型的异常会导致程序停止运行与报错

::: tip 方法一：捕获 Exception 异常的父类

可在所有指明的异常类型的最后捕获**所有异常类型的父类 [Exception 类](#expection-父类)**来实现所有异常的统一捕获

```python
try:
    # 尝试执行的代码
except Exception:
    # 异常统一捕获
```

:::

::: tip 方法二：不指明捕获的异常类型

即在所有指定类型的异常处理的最后不指明 except 捕获的异常类型来 [捕获全部异常](#捕获所有异常)，实现处理预期外的报错

```python
try:
    # 尝试执行的代码
except:
    # 统一捕获
    # 同在于无法具体到异常类型和具体错误信息
```

:::

```python
try:
    input_num = int(input('请输入整数做分母被 10 除: '))
    result = 10/input_num
except ValueError:
    print('输入的不是数字')
except:
    print('出错了', error)
else:
    print(result
```

---

### 捕获自定义异常

对于常见的错误类型直接指明捕获 `Exception` 类即可

需要指定捕获异常类型的地方一般是捕获[自定义的错误类型](https://blaxberry.github.io/vuepress-studynotes/notes/back/Python/Basic/Basic/7.ErrorException.html#自定义错误类型)

> 如下：
>
> 先指明捕获自定义的错误类型，然后捕获 Exception 统一捕获 Python 运行时的异常

```python
class CustomError(RuntimeError):
    def __init__(self, message):
        self.message = message

try:
    num = int(input('请输入数字'))
    res = 10/num

    if num % 2 == 0:
        raise CustomError("出错了啊啊啊啊啊")

except CustomError as error:
    print('自定义错误', error)

except Exception as error:
    print('Python 错误', error)
```

<br/>

## 错误信息

通过 `as` 获取**捕获到的指定的异常类型**的错误信息

```python
try:
    # 尝试执行的代码
except 错误类型A as 变量:
    pass
except Exception as 变量:
    pass
```

```python
try:
    num = int(input('请输入整数做分母被 10 除: '))
    result = 10/num

except ValueError as error:
    print('不是数字', error)

except ZeroDivisionError as error:
    print('不能作为分母', error)

except Exception as error:
    print('出错了', error)

else:
    print(result)
```

<br/>

## 错误类型

### Expection 父类

**Python 所有异常类型默认继承自 `Exception` 类**

只要捕获了 `Expection` 可直接捕获到所有作为子类的错误类型

::: danger

`Exception` 是所有错误类型的父类，在指明捕获类型后还要统一捕获异常时，一定要将捕获 `Expection` 的操作放在所有指明的类型异常捕获处理的**最后**，否则作为子类的指明的类型的异常不会被捕获到

:::

---

### 常见错误类型

反正 TMD 也记不住这么多，直接在 [指明捕获的异常类型](#捕获指定异常类型) 时直接指明捕获 `Exception` 类型就能实现异常统一捕获

```python
try:
    pass
except Exception as error:
  	print('出错了', error)
```

| BaseException             | 所有异常的基类                                     |
| ------------------------- | -------------------------------------------------- |
| SystemExit                | 解释器请求退出                                     |
| KeyboardInterrupt         | 用户中断执行(通常是输入^C)                         |
| Exception                 | 常规错误的基类                                     |
| StopIteration             | 迭代器没有更多的值                                 |
| GeneratorExit             | 生成器(generator)发生异常来通知退出                |
| StandardError             | 所有的内建标准异常的基类                           |
| ArithmeticError           | 所有数值计算错误的基类                             |
| FloatingPointError        | 浮点计算错误                                       |
| OverflowError             | 数值运算超出最大限制                               |
| ZeroDivisionError         | 除(或取模)零 (所有数据类型)                        |
| AssertionError            | 断言语句失败                                       |
| AttributeError            | 对象没有这个属性                                   |
| EOFError                  | 没有内建输入,到达 EOF 标记                         |
| EnvironmentError          | 操作系统错误的基类                                 |
| IOError                   | 输入/输出操作失败                                  |
| OSError                   | 操作系统错误                                       |
| WindowsError              | 系统调用失败                                       |
| ImportError               | 导入模块/对象失败                                  |
| LookupError               | 无效数据查询的基类                                 |
| IndexError                | 序列中没有此索引(index)                            |
| KeyError                  | 映射中没有这个键                                   |
| MemoryError               | 内存溢出错误(对于 Python 解释器不是致命的)         |
| NameError                 | 未声明/初始化对象 (没有属性)                       |
| UnboundLocalError         | 访问未初始化的本地变量                             |
| ReferenceError            | 弱引用(Weak reference)试图访问已经垃圾回收了的对象 |
| RuntimeError              | 一般的运行时错误                                   |
| NotImplementedError       | 尚未实现的方法                                     |
| SyntaxError               | Python 语法错误                                    |
| IndentationError          | 缩进错误                                           |
| TabError                  | Tab 和空格混用                                     |
| SystemError               | 一般的解释器系统错误                               |
| TypeError                 | 对类型无效的操作                                   |
| ValueError                | 传入无效的参数                                     |
| UnicodeError              | Unicode 相关的错误                                 |
| UnicodeDecodeError        | Unicode 解码时的错误                               |
| UnicodeEncodeError        | Unicode 编码时错误                                 |
| UnicodeTranslateError     | Unicode 转换时错误                                 |
| Warning                   | 警告的基类                                         |
| DeprecationWarning        | 关于被弃用的特征的警告                             |
| FutureWarning             | 关于构造将来语义会有改变的警告                     |
| OverflowWarning           | 旧的关于自动提升为长整型(long)的警告               |
| PendingDeprecationWarning | 关于特性将会被废弃的警告                           |
| RuntimeWarning            | 可疑的运行时行为(runtime behavior)的警告           |
| SyntaxWarning             | 可疑的语法的警告                                   |
| UserWarning               | 用户代码生成的警告                                 |

---

### 自定义错误类型

可以自定义错误类，**但需继承 `RuntimeError` 基类**

::: danger

因为 `Exception` 是所有错误类型的父类，指明捕获 `Exception` 类型统一捕获异常时一定要放在所有自定义类型异常捕获处理的**最后**，否则被抛出的自定义类型的异常不会被捕获到

:::

```python
class CustomError(RuntimeError):
    def __init__(self, message):
        self.message = message


try:
    num = int(input('请输入数字'))
    res = 10/num

    if num % 2 == 0:
        raise CustomError("出错了啊啊啊啊啊")

except CustomError as error:
    print('自定义错误', error)

except Exception as error:
    print('Python 错误', error)
```

<br/>

## raise 抛出异常

通过 `raise` 来自定义手动强制抛出指定的异常类型与错误信息

抛出的错误对象可以被 `try...except...` 捕获到

```python
if 条件:
    raise 错误类型(错误消息[, 参数])
```

```python
def func(password):

    if len(password) < 6:
        raise Exception('长度不够')  # 《===
    else:
        return password


try:
    res = func('123456')
except Exception as error:
    print(error)
else:
    print(res)
```

代码执行错误时系统会自动抛出[Exception 类型](#常见错误类型)的异常

`raise` **一般用于在某条件时抛出一个[自定义错误类型](#自定义错误类型)**

```python
class CustomError(RuntimeError):
    def __init__(self, message):
        self.message = message


def func(password):

    if len(password) < 6:
        raise CustomError('长度不够')
    else:
        return password


try:
  	res = func(123456)
    # res = func(0)
    # res = func(None)
except CustomError as error:
    print(error)
except Exception as error:
    print(error)
else:
    print(res)
```
